#VRML_SIM R2025a utf8
# license: Apache License 2.0
# license url: http://www.apache.org/licenses/LICENSE-2.0
# This is a proto file for Webots for the alfan_lower_body_only
# Extracted from: /home/aizar/ROBOTICS/robot-design/export_trial_urdf/robot.urdf

PROTO alfan_lower_body_only [
  field  SFVec3f     translation     0 0 0
  field  SFRotation  rotation        0 0 1 0
  field  SFString    name            "alfan_lower_body_only"  # Is `Robot.name`.
  field  SFString    controller      "void"                   # Is `Robot.controller`.
  field  MFString    controllerArgs  []                       # Is `Robot.controllerArgs`.
  field  SFString    customData      ""                       # Is `Robot.customData`.
  field  SFBool      supervisor      FALSE                    # Is `Robot.supervisor`.
  field  SFBool      synchronization TRUE                     # Is `Robot.synchronization`.
  field  SFBool      selfCollision   FALSE                    # Is `Robot.selfCollision`.
]
{
  Robot {
    translation IS translation
    rotation IS rotation
    controller IS controller
    controllerArgs IS controllerArgs
    customData IS customData
    supervisor IS supervisor
    synchronization IS synchronization
    selfCollision IS selfCollision
    children [
      Pose {
        translation -0.054847 -0.096262 -0.031289
        rotation 0.000255 -0.998800 -0.048969 0.010443
        children [
          Shape {
            appearance DEF body_material PBRAppearance {
              baseColor 0.917647 0.917647 0.917647
              roughness 1.000000
              metalness 0
            }
            geometry DEF body Mesh {
              url "alfan_lower_body_only/assets/body.stl"
            }
          }
        ]
      }
      HingeJoint {
        jointParameters HingeJointParameters {
          axis 0.000000 -0.000003 -1.000000
          anchor -0.068651 -0.140577 -0.166744
        }
        device [
          RotationalMotor {
            name "l_hip_yaw"
            maxVelocity 10.0
            minPosition -3.14159
            maxPosition 3.14159
            maxTorque 10.0
          }
          PositionSensor {
            name "l_hip_yaw_sensor"
          }
        ]
        endPoint Solid {
          translation -0.068651 -0.140577 -0.166744
          rotation 1.000000 -0.000256 0.000000 3.141590
          children [
            Pose {
              translation -0.159489 0.048929 0.183920
              rotation -0.999910 0.000000 0.013407 3.141580
              children [
                Shape {
                  appearance DEF hip_connector_material PBRAppearance {
                    baseColor 0.270588 0.270588 0.270588
                    roughness 1.000000
                    metalness 0
                  }
                  geometry DEF hip_connector Mesh {
                    url "alfan_lower_body_only/assets/hip_connector.stl"
                  }
                }
              ]
            }
            HingeJoint {
              jointParameters HingeJointParameters {
                axis -1.000000 0.000516 -0.000004
                anchor 0.028000 -0.000014 0.031798
              }
              device [
                RotationalMotor {
                  name "l_hip_roll"
                  maxVelocity 10.0
                  minPosition -3.16079
                  maxPosition 3.12239
                  maxTorque 10.0
                }
                PositionSensor {
                  name "l_hip_roll_sensor"
                }
              ]
              endPoint Solid {
                translation 0.028000 -0.000014 0.031798
                rotation -0.577564 -0.577223 0.577264 2.094143
                children [
                  Pose {
                    translation -0.000712 0.012000 0.023050
                    rotation -0.577550 0.577249 0.577252 2.094099
                    children [
                      Shape {
                        appearance DEF l_hip_mx28_block_material PBRAppearance {
                          baseColor 0.647059 0.647059 0.647059
                          roughness 1.000000
                          metalness 0
                        }
                        geometry DEF l_hip_mx28_block Mesh {
                          url "alfan_lower_body_only/assets/l_hip_mx28_block.stl"
                        }
                      }
                    ]
                  }
                  HingeJoint {
                    jointParameters HingeJointParameters {
                      axis -1.000000 -0.000003 0.000004
                      anchor -0.019950 -0.000000 0.023050
                    }
                    device [
                      RotationalMotor {
                        name "l_hip_pitch"
                        maxVelocity 10.0
                        minPosition -3.14159
                        maxPosition 3.14159
                        maxTorque 10.0
                      }
                      PositionSensor {
                        name "l_hip_pitch_sensor"
                      }
                    ]
                    endPoint Solid {
                      translation -0.019950 -0.000000 0.023050
                      rotation 0.707105 0.000001 -0.707108 3.141591
                      children [
                        Pose {
                          translation 0.000000 0.049498 -0.020500
                          rotation 1.000000 0.000256 -0.000256 1.570800
                          children [
                            Shape {
                              appearance DEF l_hip_to_knee_material PBRAppearance {
                                baseColor 0.647059 0.647059 0.647059
                                roughness 1.000000
                                metalness 0
                              }
                              geometry DEF l_hip_to_knee Mesh {
                                url "alfan_lower_body_only/assets/l_hip_to_knee.stl"
                              }
                            }
                          ]
                        }
                        HingeJoint {
                          jointParameters HingeJointParameters {
                            axis 0.000000 -0.000000 1.000000
                            anchor 0.000000 0.093837 -0.000550
                          }
                          device [
                            RotationalMotor {
                              name "l_knee_pitch"
                              maxVelocity 10.0
                              minPosition -3.11463
                              maxPosition 3.16856
                              maxTorque 10.0
                            }
                            PositionSensor {
                              name "l_knee_pitch_sensor"
                            }
                          ]
                          endPoint Solid {
                            translation 0.000000 0.093837 -0.000550
                            rotation 0.000000 0.000000 -1.000000 0.026965
                            children [
                              Pose {
                                translation -0.166768 0.053832 -0.068848
                                rotation 1.000000 0.000256 -0.000256 1.570790
                                children [
                                  Shape {
                                    appearance DEF tibia_material PBRAppearance {
                                      baseColor 0.270588 0.270588 0.270588
                                      roughness 1.000000
                                      metalness 0
                                    }
                                    geometry DEF tibia Mesh {
                                      url "alfan_lower_body_only/assets/tibia.stl"
                                    }
                                  }
                                ]
                              }
                              HingeJoint {
                                jointParameters HingeJointParameters {
                                  axis 0.000000 0.000003 -1.000000
                                  anchor -0.002494 0.092967 -0.000000
                                }
                                device [
                                  RotationalMotor {
                                    name "l_ankle_pitch"
                                    maxVelocity 10.0
                                    minPosition -3.11463
                                    maxPosition 3.16856
                                    maxTorque 10.0
                                  }
                                  PositionSensor {
                                    name "l_ankle_pitch_sensor"
                                  }
                                ]
                                endPoint Solid {
                                  translation -0.002494 0.092967 -0.000000
                                  rotation -1.000000 -0.000000 -0.000000 3.141590
                                  children [
                                    Pose {
                                      translation 0.000890 0.032988 0.019950
                                      rotation -0.999818 0.013225 -0.013737 1.570989
                                      children [
                                        Shape {
                                          appearance DEF l_ankle_mx28_block_material PBRAppearance {
                                            baseColor 0.647059 0.647059 0.647059
                                            roughness 1.000000
                                            metalness 0
                                          }
                                          geometry DEF l_ankle_mx28_block Mesh {
                                            url "alfan_lower_body_only/assets/l_ankle_mx28_block.stl"
                                          }
                                        }
                                      ]
                                    }
                                    HingeJoint {
                                      jointParameters HingeJointParameters {
                                        axis -0.999636 0.026962 -0.000004
                                        anchor 0.023042 -0.000621 0.019950
                                      }
                                      device [
                                        RotationalMotor {
                                          name "l_ankle_roll"
                                          maxVelocity 10.0
                                          minPosition -3.14159
                                          maxPosition 3.14159
                                          maxTorque 10.0
                                        }
                                        PositionSensor {
                                          name "l_ankle_roll_sensor"
                                        }
                                      ]
                                      endPoint Solid {
                                        translation 0.023042 -0.000621 0.019950
                                        rotation -0.013481 -0.999818 -0.013481 1.570982
                                        children [
                                          Pose {
                                            translation 0.013045 -0.031798 0.025250
                                            rotation -0.577550 0.577249 0.577252 2.094099
                                            children [
                                              Shape {
                                                appearance DEF l_foot_material PBRAppearance {
                                                  baseColor 0.647059 0.647059 0.647059
                                                  roughness 1.000000
                                                  metalness 0
                                                }
                                                geometry DEF l_foot Mesh {
                                                  url "alfan_lower_body_only/assets/l_foot.stl"
                                                }
                                              }
                                            ]
                                          }
                                        ]
                                        name "l_foot"
                                        boundingObject Group {
                                          children [
                                            Pose {
                                              translation 0.013000 -0.032798 0.025239
                                              rotation -0.577550 0.577249 0.577252 2.094099
                                              children [
                                                Box {
                                                   size 0.119957 0.080061 0.002000
                                                }
                                              ]
                                            }
                                            Pose {
                                              translation -0.000007 -0.009843 0.027000
                                              rotation -0.000001 1.000000 -0.000001 3.141593
                                              children [
                                                Box {
                                                   size 0.027112 0.043850 0.054000
                                                }
                                              ]
                                            }
                                          ]
                                        }
                                        physics Physics {
                                          density -1
                                          mass 0.068074
                                          centerOfMass [ 0.009583 -0.028072 0.027322 ]
                                          inertiaMatrix [
                                            7.246570e-05 9.321000e-05 3.590970e-05
                                            3.083200e-06 1.351930e-06 -3.971530e-06
                                          ]
                                        }
                                      }
                                    }
                                  ]
                                  name "l_ankle_mx28_block"
                                  boundingObject Pose {
                                    translation 0.020794 0.012944 0.018697
                                    rotation 0.999818 -0.013738 -0.013225 1.570975
                                    children [
                                      Box {
                                         size 0.084154 0.043397 0.051000
                                      }
                                    ]
                                  }
                                  physics Physics {
                                    density -1
                                    mass 0.171000
                                    centerOfMass [ 0.020530 0.010809 0.019964 ]
                                    inertiaMatrix [
                                      4.745260e-05 1.092840e-04 1.221280e-04
                                      -3.752930e-07 3.912240e-08 -3.262600e-07
                                    ]
                                  }
                                }
                              }
                            ]
                            name "tibia"
                            boundingObject Pose {
                              translation -0.003201 0.042570 -0.020500
                              children [
                                Box {
                                   size 0.039957 0.106395 0.045000
                                }
                              ]
                            }
                            physics Physics {
                              density -1
                              mass 0.033398
                              centerOfMass [ -0.007909 0.035649 -0.020500 ]
                              inertiaMatrix [
                                4.024460e-05 1.762310e-05 3.176800e-05
                                -4.875150e-06 1.788540e-11 2.021150e-11
                              ]
                            }
                          }
                        }
                      ]
                      name "l_hip_to_knee"
                      boundingObject Pose {
                        translation -0.000008 0.051837 -0.020333
                        rotation -1.000000 0.000256 0.000256 1.570800
                        children [
                          Box {
                             size 0.035760 0.045441 0.108000
                          }
                        ]
                      }
                      physics Physics {
                        density -1
                        mass 0.100000
                        centerOfMass [ 0.000020 0.076140 -0.020525 ]
                        inertiaMatrix [
                          5.823810e-05 2.075310e-05 4.998820e-05
                          4.397290e-08 -5.176750e-11 -3.323780e-07
                        ]
                      }
                    }
                  }
                ]
                name "l_hip_mx28_block"
                boundingObject Pose {
                  translation -0.001747 -0.013500 0.003731
                  rotation -0.577550 0.577249 0.577252 2.094099
                  children [
                    Box {
                       size 0.086005 0.042263 0.051000
                    }
                  ]
                }
                physics Physics {
                  density -1
                  mass 0.172000
                  centerOfMass [ -0.000137 -0.011367 0.002962 ]
                  inertiaMatrix [
                    1.245360e-04 1.110960e-04 4.734870e-05
                    6.171410e-07 4.647450e-07 -2.335470e-06
                  ]
                }
              }
            }
          ]
          name "hip_connector"
          boundingObject Pose {
            translation 0.002709 -0.000022 0.017500
            rotation 1.000000 0.000000 0.000000 3.141590
            children [
              Box {
                 size 0.050739 0.027253 0.035000
              }
            ]
          }
          physics Physics {
            density -1
            mass 0.012397
            centerOfMass [ 0.002780 -0.000001 0.009950 ]
            inertiaMatrix [
              1.867790e-06 6.451450e-06 5.695070e-06
              2.351340e-09 3.273940e-09 -1.679480e-12
            ]
          }
        }
      }
      HingeJoint {
        jointParameters HingeJointParameters {
          axis 0.000000 -0.000003 -1.000000
          anchor -0.068651 -0.051777 -0.166744
        }
        device [
          RotationalMotor {
            name "r_hip_yaw"
            maxVelocity 10.0
            minPosition -3.14159
            maxPosition 3.14159
            maxTorque 10.0
          }
          PositionSensor {
            name "r_hip_yaw_sensor"
          }
        ]
        endPoint Solid {
          translation -0.068651 -0.051777 -0.166744
          rotation 1.000000 -0.000256 0.000000 3.141590
          children [
            Pose {
              translation -0.159489 0.048929 0.183920
              rotation -0.999910 0.000000 0.013407 3.141580
              children [
                Shape {
                  appearance DEF hip_connector_2_material PBRAppearance {
                    baseColor 0.270588 0.270588 0.270588
                    roughness 1.000000
                    metalness 0
                  }
                  geometry USE hip_connector
                }
              ]
            }
            HingeJoint {
              jointParameters HingeJointParameters {
                axis -1.000000 0.000516 -0.000004
                anchor 0.028000 -0.000014 0.031798
              }
              device [
                RotationalMotor {
                  name "r_hip_roll"
                  maxVelocity 10.0
                  minPosition -3.16079
                  maxPosition 3.12239
                  maxTorque 10.0
                }
                PositionSensor {
                  name "r_hip_roll_sensor"
                }
              ]
              endPoint Solid {
                translation 0.028000 -0.000014 0.031798
                rotation -0.577564 -0.577223 0.577264 2.094143
                children [
                  Pose {
                    translation 0.000712 0.012000 0.023050
                    rotation -0.577550 0.577249 0.577252 2.094099
                    children [
                      Shape {
                        appearance DEF r_hip_mx28_block_material PBRAppearance {
                          baseColor 0.647059 0.647059 0.647059
                          roughness 1.000000
                          metalness 0
                        }
                        geometry DEF r_hip_mx28_block Mesh {
                          url "alfan_lower_body_only/assets/r_hip_mx28_block.stl"
                        }
                      }
                    ]
                  }
                  HingeJoint {
                    jointParameters HingeJointParameters {
                      axis 1.000000 0.000000 -0.000004
                      anchor 0.019950 -0.000000 0.023050
                    }
                    device [
                      RotationalMotor {
                        name "r_hip_pitch"
                        maxVelocity 10.0
                        minPosition -3.14159
                        maxPosition 3.14159
                        maxTorque 10.0
                      }
                      PositionSensor {
                        name "r_hip_pitch_sensor"
                      }
                    ]
                    endPoint Solid {
                      translation 0.019950 -0.000000 0.023050
                      rotation -0.000000 1.000000 0.000000 1.570800
                      children [
                        Pose {
                          translation 0.000000 -0.049498 -0.020500
                          rotation -1.000000 -0.000256 -0.000256 1.570800
                          children [
                            Shape {
                              appearance DEF r_hip_to_knee_material PBRAppearance {
                                baseColor 0.647059 0.647059 0.647059
                                roughness 1.000000
                                metalness 0
                              }
                              geometry DEF r_hip_to_knee Mesh {
                                url "alfan_lower_body_only/assets/r_hip_to_knee.stl"
                              }
                            }
                          ]
                        }
                        HingeJoint {
                          jointParameters HingeJointParameters {
                            axis -0.000000 -0.000000 1.000000
                            anchor 0.000000 -0.093837 -0.000550
                          }
                          device [
                            RotationalMotor {
                              name "r_knee_pitch"
                              maxVelocity 10.0
                              minPosition -3.16856
                              maxPosition 3.11463
                              maxTorque 10.0
                            }
                            PositionSensor {
                              name "r_knee_pitch_sensor"
                            }
                          ]
                          endPoint Solid {
                            translation 0.000000 -0.093837 -0.000550
                            rotation -0.000000 -0.000000 1.000000 0.026965
                            children [
                              Pose {
                                translation -0.166768 -0.053832 0.027848
                                rotation -1.000000 -0.000256 -0.000256 1.570800
                                children [
                                  Shape {
                                    appearance DEF tibia_2_material PBRAppearance {
                                      baseColor 0.270588 0.270588 0.270588
                                      roughness 1.000000
                                      metalness 0
                                    }
                                    geometry USE tibia
                                  }
                                ]
                              }
                              HingeJoint {
                                jointParameters HingeJointParameters {
                                  axis -0.000000 -0.000003 -1.000000
                                  anchor -0.002494 -0.092967 -0.000000
                                }
                                device [
                                  RotationalMotor {
                                    name "r_ankle_pitch"
                                    maxVelocity 10.0
                                    minPosition -3.16856
                                    maxPosition 3.11463
                                    maxTorque 10.0
                                  }
                                  PositionSensor {
                                    name "r_ankle_pitch_sensor"
                                  }
                                ]
                                endPoint Solid {
                                  translation -0.002494 -0.092967 -0.000000
                                  rotation 1.000000 0.000000 -0.000000 3.141590
                                  children [
                                    Pose {
                                      translation 0.000890 -0.032988 0.019950
                                      rotation 0.999818 0.013738 0.013225 1.570975
                                      children [
                                        Shape {
                                          appearance DEF r_ankle_mx28_block_material PBRAppearance {
                                            baseColor 0.647059 0.647059 0.647059
                                            roughness 1.000000
                                            metalness 0
                                          }
                                          geometry DEF r_ankle_mx28_block Mesh {
                                            url "alfan_lower_body_only/assets/r_ankle_mx28_block.stl"
                                          }
                                        }
                                      ]
                                    }
                                    HingeJoint {
                                      jointParameters HingeJointParameters {
                                        axis -0.999637 -0.026959 0.000004
                                        anchor 0.023042 0.000621 0.019950
                                      }
                                      device [
                                        RotationalMotor {
                                          name "r_ankle_roll"
                                          maxVelocity 10.0
                                          minPosition -3.14159
                                          maxPosition 3.14159
                                          maxTorque 10.0
                                        }
                                        PositionSensor {
                                          name "r_ankle_roll_sensor"
                                        }
                                      ]
                                      endPoint Solid {
                                        translation 0.023042 0.000621 0.019950
                                        rotation 0.707073 0.009533 -0.707076 3.122528
                                        children [
                                          Pose {
                                            translation -0.013045 -0.031798 0.025250
                                            rotation -0.577550 0.577249 0.577252 2.094099
                                            children [
                                              Shape {
                                                appearance DEF r_foot_material PBRAppearance {
                                                  baseColor 0.647059 0.647059 0.647059
                                                  roughness 1.000000
                                                  metalness 0
                                                }
                                                geometry DEF r_foot Mesh {
                                                  url "alfan_lower_body_only/assets/r_foot.stl"
                                                }
                                              }
                                            ]
                                          }
                                        ]
                                        name "r_foot"
                                        boundingObject Group {
                                          children [
                                            Pose {
                                              translation 0.000011 -0.009899 0.027000
                                              rotation 1.000000 -0.000000 0.000000 3.141590
                                              children [
                                                Box {
                                                   size 0.027233 0.043866 0.054000
                                                }
                                              ]
                                            }
                                            Pose {
                                              translation -0.012938 -0.032798 0.025295
                                              rotation -0.577550 0.577249 0.577252 2.094099
                                              children [
                                                Box {
                                                   size 0.120686 0.080481 0.002000
                                                }
                                              ]
                                            }
                                          ]
                                        }
                                        physics Physics {
                                          density -1
                                          mass 0.068074
                                          centerOfMass [ -0.009583 -0.028072 0.027322 ]
                                          inertiaMatrix [
                                            7.246570e-05 9.321000e-05 3.590970e-05
                                            -3.083200e-06 -1.351930e-06 -3.971530e-06
                                          ]
                                        }
                                      }
                                    }
                                  ]
                                  name "r_ankle_mx28_block"
                                  boundingObject Pose {
                                    translation 0.020689 -0.012947 0.018687
                                    rotation -0.999818 -0.013225 0.013737 1.570989
                                    children [
                                      Box {
                                         size 0.084021 0.043283 0.051000
                                      }
                                    ]
                                  }
                                  physics Physics {
                                    density -1
                                    mass 0.171000
                                    centerOfMass [ 0.020530 -0.010809 0.019964 ]
                                    inertiaMatrix [
                                      4.745260e-05 1.092840e-04 1.221280e-04
                                      3.753010e-07 3.913340e-08 3.262620e-07
                                    ]
                                  }
                                }
                              }
                            ]
                            name "tibia_2"
                            boundingObject Pose {
                              translation -0.003201 -0.042570 -0.020500
                              rotation 1.000000 -0.000000 -0.000000 3.141590
                              children [
                                Box {
                                   size 0.039957 0.106395 0.045000
                                }
                              ]
                            }
                            physics Physics {
                              density -1
                              mass 0.033398
                              centerOfMass [ -0.007909 -0.035649 -0.020500 ]
                              inertiaMatrix [
                                4.024460e-05 1.762310e-05 3.176800e-05
                                4.875150e-06 -1.788540e-11 2.021150e-11
                              ]
                            }
                          }
                        }
                      ]
                      name "r_hip_to_knee"
                      boundingObject Pose {
                        translation 0.000008 -0.051837 -0.020376
                        rotation 1.000000 -0.000256 0.000256 1.570800
                        children [
                          Box {
                             size 0.035752 0.045425 0.108000
                          }
                        ]
                      }
                      physics Physics {
                        density -1
                        mass 0.100000
                        centerOfMass [ 0.000020 -0.076140 -0.020525 ]
                        inertiaMatrix [
                          5.823810e-05 2.075310e-05 4.998820e-05
                          -4.397090e-08 -4.880360e-11 3.323610e-07
                        ]
                      }
                    }
                  }
                ]
                name "r_hip_mx28_block"
                boundingObject Pose {
                  translation 0.001264 -0.013500 0.003704
                  rotation -0.577550 0.577249 0.577252 2.094099
                  children [
                    Box {
                       size 0.086166 0.043316 0.051000
                    }
                  ]
                }
                physics Physics {
                  density -1
                  mass 0.172000
                  centerOfMass [ -0.000014 -0.011279 0.003118 ]
                  inertiaMatrix [
                    1.243550e-04 1.113070e-04 4.769150e-05
                    -3.248820e-07 4.713790e-08 -2.619350e-06
                  ]
                }
              }
            }
          ]
          name "hip_connector_2"
          boundingObject Pose {
            translation 0.002709 -0.000022 0.017500
            rotation 1.000000 0.000000 0.000000 3.141590
            children [
              Box {
                 size 0.050739 0.027253 0.035000
              }
            ]
          }
          physics Physics {
            density -1
            mass 0.012397
            centerOfMass [ 0.002780 -0.000001 0.009950 ]
            inertiaMatrix [
              1.867790e-06 6.451450e-06 5.695070e-06
              2.351340e-09 3.273940e-09 -1.679480e-12
            ]
          }
        }
      }
    ]
    name IS name
    boundingObject Group {
      children [
        Pose {
          translation -0.055462 -0.051776 -0.148645
          rotation 1.000000 -0.000256 0.000000 3.141590
          children [
            Box {
               size 0.051779 0.036098 0.041900
            }
          ]
        }
        Pose {
          translation -0.055412 -0.140566 -0.148645
          rotation 1.000000 -0.000256 0.000000 3.141590
          children [
            Box {
               size 0.051622 0.035888 0.041900
            }
          ]
        }
        Pose {
          translation -0.059044 -0.096047 -0.079955
          rotation 0.577351 0.577350 0.577351 2.094402
          children [
            Box {
               size 0.124406 0.098224 0.065000
            }
          ]
        }
      ]
    }
    physics Physics {
      density -1
      mass 0.464000
      centerOfMass [ -0.060159 -0.096184 -0.094045 ]
      inertiaMatrix [
        1.690170e-03 1.070440e-03 8.603090e-04
        6.312770e-09 4.508320e-05 6.797110e-08
      ]
    }
  }
}
